Count,Message,Traceback,Nodes
39860,'module' object is not callable,"  File ""/Users/kdipanjan/my_projects/pythonProject/venv/lib/python3.12/site-packages/locust/user/task.py"", line 340, in run
    self.execute_next_task()
  File ""/Users/kdipanjan/my_projects/pythonProject/venv/lib/python3.12/site-packages/locust/user/task.py"", line 373, in execute_next_task
    self.execute_task(self._task_queue.popleft())
  File ""/Users/kdipanjan/my_projects/pythonProject/venv/lib/python3.12/site-packages/locust/user/task.py"", line 490, in execute_task
    task(self.user)
",local
